Workbook
Name Hoje: TODAY()
Name Incremento_de_rolagem: #REF!
Name Incremento_de_rolagem: #REF!
Name Incremento_de_rolagem: #REF!
Name Incremento_de_rolagem: #REF!
Name Incremento_de_rolagem: #REF!
Name Incremento_de_rolagem: #REF!
Name Incremento_de_rolagem: 'Grafico Gantt '!$F$4
Name Incremento_de_rolagem: #REF!
Name Incremento_de_rolagem: #REF!
Name Início_do_projeto: #REF!
Name Início_do_projeto: #REF!
Name Início_do_projeto: #REF!
Name Início_do_projeto: #REF!
Name Início_do_projeto: #REF!
Name Início_do_projeto: #REF!
Name Início_do_projeto: 'Grafico Gantt '!$F$3
Name Início_do_projeto: #REF!
Name Início_do_projeto: #REF!

Sheet EAP (2)

Sheet Dicionario EAP
D1: Lider | G1: Leandro Costa Ferreira | J1: DATA DE INICIO 13/08/2023 | M1: DATA DE ENTREGA 01/12/2022
D2: Equipe | G2: Pétrick Gomes
G3: Cosme Sousa
G4: Damião Sousa
G5: Nilton Guerra
G6: João Miranda
A7: PLANEJAMENTO | B7: Termo de Abertura do Projeto (TAP) | C7: Pacote de Trabalho | D7: Descrição | E7: Criterios de Aceitação | F7: (R) Responsavel | G7: (A) Autoridade | H7: (C) Consultado | I7: (I) Informado | J7: O quê? | K7: Por quê? | L7: Onde? | M7: quem? | N7: Como?
C8: Formalização do Projeto. | D8: A Formalização do Projeto, é uma garantia que o grupo tem para impulsionar adequadamento o projeto. É importante , pois oficializa as metas que foram cumpridas, gerandos obrigações. Serve para assegurar a entrega do projeto. | E8: Especificar o objetivo central do projeto. | F8: Todos integrantes | G8: Leandro Costa Ferreira Pétrick Gomes | H8: Todos integrantes | I8: Todos integrantes | J8: Formalizar o projeto e as obrigações de todos os integrantes. | K8: Criar responsabilidade para os integrantes do grupo, para auxiliar no desenvolvimento do projeto e inserção dos integrantes nele. | L8: Sala de aula C13. | M8: Todos os integrantes do grupo | N8: Através de um brainstorm de todos os integrantes que irá ser registrado na TAP no projeto
C10: Estrutura e organização das ideias do projeto. | D10: Estruturar e organizar o projeto é uma etapa importante para que os integrantes tenham o controle sobre as ideias e tarefas que serão executadas. | E10: Direcionar os integrantes a seus objetivos. | F10: Todos integrantes | G10: Leandro Costa Ferreira Pétrick Gomes | H10: Todos integrantes | I10: Todos integrantes | J10: Estruturar as ideias do projeto. | K10: Ter uma lógistica de tarefas fácil de se gerir . | L10: Sala de aula C13. | M10: Todos os integrantes do grupo | N10: Através de um brainstorm de todos os integrantes que irá ser registrado na TAP no projeto
C12: Análise dos Integrantes pelo metodo SWOT. | D12: Analisar os integrantes por meio do método SWOT é um ponto extremamente relevante que serve para conhecer as limitaçãoes de cada um, facilitandona definição de funções. | E12: Facilitar o reconhecimento das limitações e acrecismos dos integrantes do Projeto. | F12: Todos integrantes | G12: Leandro Costa | H12: Todos integrantes | I12: Todos integrantes | J12: verificar as forças e fraquezas de todos os integrantes do grupo. | K12: Facilitar na atribuição de tarefas de todos os integrantes do grupo. | L12: Sala de aula C13. | M12: Todos os integrantes do grupo | N12: Através de um brainstorm de todos os integrantes que irá ser registrado na TAP no projeto
C13: Atribuição de Responsabilidades e Funções. | D13: Atribuir responsabilidades e funções de acordo com a capacidade de cada um é um ponto importante para o desenvolvimento do trabalho, pois cada integrante pode ser responsabilizado por uma função que tenha maior facilidade na realização. | E13: Atribuição de reponsabilidades de integrantes expecificos em determinadas temas. | F13: Todos integrantes | G13: Leandro Costa Ferreira Pétrick Gomes | H13: Todos integrantes | I13: Todos integrantes | J13: Atribuir responsabilidades a todos os integrantes do grupo. | K13: Agilizar a realização do projeto | L13: Sala de aula C08 | M13: Todos os integrantes do grupo | N13: Através de um brainstorm de todos os integrantes que irá ser registrado na TAP no projeto
C15: Revisão. | D15: Revisar o que já foi feito nesta tarefa por cada integrante. Sempre visando o aperfeiçoamento do documento ou trabalho, caso necessário. | E15: Gerar um aprimoramento no que já foi feito. | F15: Todos integrantes | G15: Leandro Costa Ferreira | H15: Todos integrantes | I15: Todos integrantes | J15: Revisar o trabalho | K15: Corrigir possiveis erros gramáticais e | L15: Sala de aula C08 | M15: Todos os integrantes do grupo | N15: Consultando integrantes do grupo e professores.
C16: Validação. | D16: Validar o trabalho feito nesta etapa e revisar caso seja necessário. | E16: Cumprir com os criterios passados em sala de aula e do PMBOK. | F16: Orientadores | G16: Orientadores | H16: Orientadores | I16: Orientadores | J16: Validação | K16: Fazer uma segunda revisão para verificar possiveis erros. | L16: Sala de aula C08 | M16: Todos os integrantes do grupo | N16: Consultando professores
B17: Escopo | C17: Definição de Etapas. | D17: Definir a ordem de como e quando será feito cada etapa. | E17: Definir e separar as principais renponsabilidades em etapas. | F17: Cosme Sousa Damião Sousa Nilton Guerra | G17: Leandro Costa Ferreira Pétrick Gomes | H17: Todos integrantes | I17: Todos integrantes | J17: Definir como e quando serão realizadas as atividas e etapas do projeto. | K17: Facilitar a gestão do projeto. | L17: Sala de aula C08 | M17: Todos os integrantes do grupo | N17: Através de um brainstrom entre os integrantes do grupo e usando uma planilha do excel definimos as etapas do projeto
C20: Definição de Tarefas. | D20: Definir quais tarefas e subtarefas a serem executadas em cada etapa do processo. | E20: Desmembrar as etapas em tarefas. | F20: Cosme Sousa Damião Sousa Nilton Guerra | G20: Leandro Costa Ferreira Pétrick Gomes | H20: Todos integrantes | I20: Todos integrantes | J20: Definir como e quando serão realizadas as atividas e etapas do projeto. | K20: Facilitar na gestão do projeto | L20: Sala de aula C08 | M20: Todos os integrantes do grupo | N20: Através de um brainstrom entre os integrantes do grupo nos definimos onde cada tarefa se alocará
C23: Dicionario. | D23: Descrição de cada subtarefa e definir os responsaveis pela execução conforme o nivel de responsabilidade mostrado na tabela RACI e na analise SWOT. | E23: Direcionar de maneira mais profundada a todos os processos do projeto. | F23: Leandro Costa Ferreira Pétrick Gomes João Miranda | G23: Leandro Costa Ferreira Pétrick Gomes | H23: Todos integrantes | I23: Todos integrantes | J23: Descrever as tarefas a serem executadas pelos integrantes baseado na análise SWOT e RACI | K23: Facilitar na gestão do projeto e trazer mais facilidade na execução do trabalho | L23: Sala de aula C08 | M23: Todos os integrantes do grupo | N23: Através de uma divisão dos integrantes nos montamos o dicionário da EAP usando e software da microsoft Excel.
C26: Revisão. | D26: Revisar o que foi já feito nesta tarefa por cada integrante, aperfeiçoando o documento, caso necessário. | E26: Gerar um aprimoramento naquilo que já foi executado. | F26: Todos integrantes | G26: Leandro Costa Ferreira Pétrick Gomes | H26: Todos integrantes | I26: Todos integrantes | J26: Revisar o que se foi feito. | K26: verificar se o que foi feito está bom e sugerir possiveis melhorias. | L26: Sala de aula C08 | M26: Todos os integrantes do grupo | N26: Uma leitura da TAP pelo lider e vice-lider
C28: Validação. | D28: Validar o trabalho feito nesta etapa e revisar caso necessário. | E28: Cumprir com os criterios passados em sala de aula e do PMBOK. | F28: Orientadores | G28: Orientadores | H28: Orientadores | I28: Orientadores | J28: validar o trabalho que foi feito nessa etapa | K28: Verificar se o que foi feito está bom. | L28: Sala de aula C08 | M28: Todos os integrantes do grupo | N28: Uma leitura da TAP pelo lider e vice-lider
B29: Cronograma | C29: Análise do escopo | D29: Analisar o escopo é importante para a organização do grupo em relação a tarefas e responsabilidades. | E29: Finalidade do Projeto, a meta final. | F29: Leandro Costa Pétrick Gomes | G29: Leandro Costa Ferreira Pétrick Gomes | H29: Cosme Sousa Damião Sousa | I29: Todos integrantes | J29: Análisar o escopo | K29: Criar o sentimento para cada integrantes de responsabilidade com a tarefa atribuida a ele. | L29: C13 | M29: Leandro Costa Petrick Gomes | N29: Através de uma conversa entre os integrantes nos iremos revidar as divições das tarefas
C32: Definição do tempo de trabalho | D32: Definir o tempo de trabalho é de extrema importância, pois serve para estimar prazos e também para ter o controle do tempo que será gasto com cada etapa, facilitando a organização do projeto. | E32: Levar um tempo de trabalho necessario e esperado. | F32: Leandro Costa Pétrick Gomes | G32: Leandro Costa Ferreira Pétrick Gomes | H32: Todos integrantes | I32: Todos integrantes | J32: Definir o tempo para realizar cada etapa | K32: Permitir que entregue o projeto a tempo | L32: C13 | M32: Leandro Costa Petrick Gomes | N32: Através da formula de PER, usando o software Excel e uma brainstorm com todos os integrantes definimos as tarefas a serem realizadas.
C34: Definição de datas de entrega | D34: Designar as datas de entrega é extremamente importante para a organização e a finalização do projeto, com uma data de entrega pré-definida, os integrantes conseguem se organizar e definir tarefas facilmente. | E34: Levar uma elaboração antecipada. | F34: Leandro Costa Pétrick Gomes | G34: Leandro Costa Ferreira Pétrick Gomes | H34: Todos integrantes | I34: Todos integrantes | J34: Definir datas para a entrega de cada parte do trabalho | K34: Facilitar na gestão do projeto | L34: C13 | M34: Leandro Costa Petrick Gomes | N34: Através da formula de PER, usando o software Excel e uma brainstorm de todos os integrantes definimos as tarefas a serem realizadas.
C36: Revisão | D36: Revisar o que foi já feito nesta tarefa por cada integrante, aperfeiçoando o documento, caso necessário. | E36: Gerar um aprimoramento naquilo que já foi executado. | F36: Leandro Costa Pétrick Gomes | G36: Leandro Costa Ferreira Pétrick Gomes | H36: Todos integrantes | I36: Todos integrantes | J36: Revisar o que se foi feito. | K36: Sujerir posiveis melhorias e evitar possiveis erros | L36: C13 | M36: Leandro Costa Petrick Gomes | N36: Uma leitura da TAP pelo lider e vice-lider
C37: Validação | D37: Validar o documento feito nessa etapa e revisar caso necessário. | E37: Cumprir com os criterios passados em aula e do PMBOK. | F37: Orientadores | G37: Orientadores | H37: Orientadores | I37: Orientadores | J37: validar o que se foi feito | K37: Sujerir posiveis melhorias e evitar possiveis erros | L37: C13 | M37: Leandro Costa Petrick Gomes | N37: Uma leitura da TAP pelo lider e vice-lider
B38: Analises de Risco do Projeto | C38: Avaliação de impacto | D38: Avaliar os possiveis riscos que podem prejudicar o projeto. | E38: Levantar os possiveis riscos. | F38: Todos integrantes | G38: Leandro Costa Ferreira Pétrick Gomes | H38: Todos integrantes | I38: Todos integrantes | J38: Avaliar os possíveis riscos do projeto | K38: evitar/ amenizar os riscos ao projeto | L38: C13 | M38: Leandro Costa Ferreira Pétrick Gomes João Miranda | N38: Através de um brainstorm de todos os responsaveis iremos abordar possiveis estratégias para evitar os riscos.
C41: Avaliação de probabilidade | D41: Avaliar a probabilidade desses riscos acontecerem e quando pode ser que aconteçam. | E41: Preparar-se sob a probabilidade dos riscos. | F41: Todos integrantes | G41: Leandro Costa Ferreira Pétrick Gomes | H41: Todos integrantes | I41: Todos integrantes | J41: Avaliar a probabilidade dos riscos acontecerem. | K41: Fazer preparações de acordo com o nivel de probabilidade. | L41: C13 | M41: Leandro Costa Ferreira Pétrick Gomes João Miranda | N41: Através de um brainstorm de todos os responsaveis considerar quais os riscos mais prováveis.
C44: Peso de risco | D44: O quão pode ser prejucial caso algum risco aconteça e o que fazer para nos recuperar. | E44: Gerar possiveis consequencias. | F44: Todos integrantes | G44: Leandro Costa Ferreira Pétrick Gomes | H44: Todos integrantes | I44: Todos integrantes | J44: definir o quão grave é o risco e as medidas de supressão dele. | K44: definir o que será feito caso um risco aconteça. | L44: C13 | M44: Leandro Costa Ferreira Pétrick Gomes João Miranda | N44: Através de um brainstorm de todos os responsaveis iremos abordar possiveis estratégias para evitar os riscos.
C47: Burndown chart | D47: É um grafico que demonstra o tempo versus o trabalho a ser feito. | E47: Comparar o tempo trabalho com a meta. | F47: Todos integrantes | G47: Leandro Costa Ferreira Pétrick Gomes | H47: Todos integrantes | I47: Todos integrantes | J47: Fazer um gráfico de acompanhamento do trabalho | K47: Saber que velocidade o projeto está caminhando para poder gerar uma possivel data de entrega. | L47: C13 | M47: Leandro Costa Ferreira Pétrick Gomes João Miranda | N47: Através da formula de PER iremos desenvolver quanto tempo é necessário para a execução de cada tarefa do projeto e com essa informação iremos estimar uma valor em pontos para cada atividade que por fim será usado no gráfico do burndown chart juntamente com o tempo disponivel.
A50: INSTALAÇÃO | B50: Painéis | C50: Dimencionar quadro de distribuição | D50: Definir o tamanho do quadro de distribuição com o objetivo de trazer uma sensação visial melhor e facilitar possiveis aprimoramentos da instalação. | E50: permitir que todos os quadros de energia possam ser instalados dentro do quadro de distribuição | G50: Leandro Costa Ferreira Pétrick Gomes | H50: Leandro Costa Ferreira Pétrick Gomes | I50: Todos os integrantes | J50: Usar a escala de mm para definir o tamanho do quadro de distribuição que conterá os quadros de iluminação, CFTV e alarme de incêndio. | K50: Para trazer uma sensação visual melhor, evitar gastos desnecessários e facilitar possiveis aprimoramentos da instalação. | L50: oficina IELI 1 | M50: Cosme Alves Damião Alves | N50: Através de um técnico altamente treinado irá ser feito um dimenciosamento do sistema elétrico da instalação e com essa insformação iremos definir a quantidade de componentes necessarios para a instalação e assim a dimenção do quadro
C52: dimencionar quadro de força. | D52: Proteger os circuitos da instalação de qualquer anormalidade da rede de energia. | E52: proteger o circuito de iluminação | G52: Leandro Costa Ferreira Pétrick Gomes | H52: Leandro Costa Ferreira Pétrick Gomes | I52: Todos os integrantes | J52: Usar disjuntor, DPS e DR para a proteção do circuito de iluminação. | K52: proteger o circuito. | L52: oficina IELI 1 | M52: Cosme Alves Damião Alves | N52: Usando os conhecimento adquiridos pelo curso de eletroeletrônica do SENAI, iremos dimencionar o quadro de força
B54: Instalação do CFTV | C54: Passagem de cabos | D54: Fazer a transmição de dados e de energia elétrica através de eletrocalhas e eletrodutos | E54: Fazer a alimentação das câmeras e do DRV com condutores isolados e sem imendas nos eletrodutos. | F54: Damião sousa | G54: Leandro Costa Ferreira Pétrick Gomes | H54: Leandro Costa Ferreira Pétrick Gomes | I54: Todos os integrantes | J54: Passar os cabos pelos eletrodutos. | K54: Permitir a alimentação dos componentes | L54: oficina IELI 1 | M54: Nilton Guerra Cosme Alves | N54: Fazer o dimensionamento dos cabos para a instalação das câmeras
C56: Instalar câmeras | D56: colocar as câmeras nos locais previamente definidos para possibilitar o monitoramento dos locais. | E56: Fixar firme as câmeras e fazer a alimentação e a transmição de dados com facilidade. | F56: Damião sousa | G56: Leandro Costa Ferreira Pétrick Gomes | H56: Leandro Costa Ferreira Pétrick Gomes | I56: Todos os integrantes | J56: Instalar apoios para as câmeras através de parafusos e porcas, para logo em seguida colocar as câmeras. | K56: Para permitir a monitoração de locais previamentes desiginados. | L56: oficina IELI 1 | M56: Nilton Guerra Cosme Alves | N56: definir posição para instalação das câmeras
C58: Instalar Central | D58: Instalar o DVR e o monitor para possibilitar o acompanhamento da vigilância dos locais. | E58: Permitir a comunicação do monitor com o DRV | F58: Damião sousa | G58: Leandro Costa Ferreira | H58: Leandro Costa Ferreira | I58: Todos os integrantes | J58: usar o cabo VGA para comunicar o DVR com o monitor e alimentar ambos. | K58: Para permitir o acompanhamneto da vigilância dos locais pelo monitor. | L58: oficina IELI 1 | M58: Nilton Guerra Cosme Alves | N58: Interligação do DVR com o monitor
C60: Interligar as câmeras com a central | D60: Permitir a transmição de dados entre as câmeras e o DVR | E60: Permitir a visualização dos pontos de vigilância no monitor | F60: Damião sousa | G60: Leandro Costa Ferreira | H60: Leandro Costa Ferreira | I60: Todos os integrantes | J60: usando o conector P4 macho e fême e o cabo coaxial fazer o interligamento da câmera com o DVR. | K60: Comunicar o DVR com as câmeras. | L60: oficina IELI 1 | M60: Nilton Guerra | N60: Interligação das câmeras com Central para ser feito monitoriamento com DVR
B61: Instalação da central | C61: Passagem de cabos. | D61: Permitir que haja a transmição de energia | E61: Que os cabos passados sejam alimentados e devidamente isolados sem imentas nos eletrodutos. | F61: Nilton Gerra | G61: Leandro Costa Ferreira Pétrick Gomes | H61: Leandro Costa Ferreira Pétrick Gomes | I61: Todos os integrantes | J61: Passar os cabos pelos eletrodutos. | K61: Permitir a alimentação dos componentes | L61: oficina IELI 1 | M61: Nilton Guerra | N61: Usando um guia passa fio iremos direcionar os cabos para suas devidas posições já estipuladas no planejamento.
C63: Instalar sensores e atuadores manuais. | D63: permitir que haja a sensibilidade para captar fumaça. | E63: Ligar todas as coneções dos sensores corretamente. | F63: Nilton Gerra | G63: Leandro Costa Ferreira Pétrick Gomes | H63: Leandro Costa Ferreira Pétrick Gomes | I63: Todos os integrantes | J63: instalar os sensores de fumaça respeitando as suas coneções com a central de incêndio,1:1,2:2,3:3,4:4 | K63: Permitir a captura de fumaça | L63: oficina IELI 1 | M63: Nilton Guerra | N63: Usando a escada e uma chave de fenda iremos instalar os sensores de fumaça respeitando a posição de cada cabo.
C65: Instalar Central. | D65: Definir um local específico para gerenciar o controle de incêndios. | E65: Fazer a comunicação entre central de alarme de incêndio e sesores de fumaça. | F65: Nilton Gerra | G65: Leandro Costa Ferreira Pétrick Gomes | H65: Leandro Costa Ferreira Pétrick Gomes | I65: Todos os integrantes | J65: posicionar um local especifico para gerenciar o controle de incêndio | K65: ter um controle mais rápido e eficiente do sistema de incêndio | L65: oficina IELI 1 | M65: Nilton Guerra | N65: definir uma posição para a central de incêndio que não incomode ninguém
B67: Instalação de Iluminação | C67: Passagem de cabos | D67: Permitir que haja a transmição de energia | E67: Que os cabos passados sejam alimentados e devidamente isolados sem imentas nos eletrodutos. | F67: Cosme Sousa | G67: Leandro Costa Ferreira Pétrick Gomes | H67: Leandro Costa Ferreira Pétrick Gomes | I67: Todos os integrantes | J67: Passar os cabos pelos eletrodutos. | K67: Permitir a alimentação dos componentes | L67: oficina IELI 1 | M67: Cosme Sousa | N67: Usando um passa fio iremos direcionar os cabos para suas devidas posições já estipuladas no planejamento.
C69: Instalar lâmpadas LED | D69: Iluminar os recintos através de uma lampada LED de valor especificado na NBR5410. | E69: Fazer as lampadas acenderem. | F69: Cosme Sousa | G69: Leandro Costa Ferreira Pétrick Gomes | H69: Leandro Costa Ferreira Pétrick Gomes | I69: Todos os integrantes | J69: Fazer a instalação dos receptaculos, e logo em seguida colocar as lampadas LED | K69: Iluminar o ambiente | L69: oficina IELI 1 | M69: Cosme Sousa | N69: Usando uma escada iremos instalar a lampada no receptaculo.
C71: Instalação dos interruptores móveis. | D71: Facilitar a configução dos interruptores móvéis com o objetivo de trazer mais conforto no acionamento da iluminação do local. | E71: Fazer a instalação dos interruptores móveis com condutores sem imendas e sem partes de cobre a mostra. | F71: Cosme Sousa | G71: Leandro Costa Ferreira Pétrick Gomes | H71: Leandro Costa Ferreira Pétrick Gomes | I71: Todos os integrantes | J71: Instalação dos interruptores móveis | K71: configução dos interruptores móvéis com o objetivo de trazer conforto. | L71: oficina IELI 1 | M71: Cosme Sousa | N71: usando o interruptor móvel, um interruptor pulsador e o aplicativo do interruptor idemos sincronizar-los.
C73: Configuração dos interruptores móveis | D73: Configurar os interruptores móveis para que possa ocorrer o acionamento da iluminação do recintos de maneira mais cômoda. | E73: Fazer os interruptores móveis funcionarem | F73: Cosme Sousa | G73: Leandro Costa Ferreira Pétrick Gomes | H73: Leandro Costa Ferreira Pétrick Gomes | I73: Todos os integrantes | J73: configuração dos interruptores | K73: Fazer os interruptores móveis funcionarem | L73: oficina IELI 1 | M73: Cosme Sousa | N73: Usando o aplicativo do interruptor movél iremos configurar o aplicativo.
...

Sheet Dicionario EAP2
D1: AUTOMOÇÃO PREDIAL | G1: LIDER | I1: LEANDRO COSTA FERREIRA | K1: DATA DE INICIO 13/08/2023 | M1: DATA DE ENTREGA 01/12/2022
W2: x
G7: EQUIPE | I7: Pétrick Gomes
I8: Cosme Sousa
I9: Damião Sousa
I10: Nilton Guerra | W10: AGOSTO | Z10: SETEMBRO | AD10: OUTUBRO | AI10: NOVEMBRO | AM10: DEZEMBRO
I11: João Miranda
W13: SEMANA 1 | X13: SEMANA 2 | Y13: SEMANA 3 | Z13: SEMANA 4 | AA13: SEMANA 5 | AB13: SEMANA 6 | AC13: SEMANA 7 | AD13: SEMANA 8 | AE13: SEMANA 9 | AF13: SEMANA 10 | AG13: SEMANA 11 | AH13: SEMANA 12 | AI13: SEMANA 13 | AJ13: SEMANA 14 | AK13: SEMANA 15 | AL13: SEMANA 16 | AM13: SEMANA 17
C14: Criterios de Aceitação | D14: O quê? | E14: Por quê? | F14: Onde? | G14: quem? | H14: Como? | I14: Quando? | N14: Quanto? | R14: RISCO | S14: PESO | T14: PROGRESO | U14: PESO EX | W14: 44421 | X14: =W14+7 -> 44428 | Y14: =X14+7 -> 44435 | Z14: =Y14+7 -> 44442 | AA14: =Z14+7 -> 44449 | AB14: =AA14+7 -> 44456 | AC14: =AB14+7 -> 44463 | AD14: =AC14+7 -> 44470 | AE14: =AD14+7 -> 44477 | ... AL14: =AK14+7 -> 44526 | AM14: =AL14+5 -> 44531
I15: inicio | J15: Otimista | K15: MP | L15: Pessimista | M15: Pert
A16: PLANEJAMENTO | B16: Termo de Abertura do Projeto (TAP | C16: Especificar o objetivo central do projeto. | D16: Formalizar o projeto e as obrigações de todos os integrantes. | E16: Criar responsabilidade para os integrantes do grupo, para auxiliar no desenvolvimento do projeto e inserção dos integrantes nele. | F16: Sala de aula C13. | G16: equipe | H16: Através de um brainstorm de todos os integrantes que irá ser registrado na TAP no projeto | I16: 44421 | J16: 4 | K16: 8 | L16: 12 | M16: =(J16+(4*K16)+L16)/6 -> 8 | N16: =SUM($S$93:$S$96)*M16 -> 809.2 | R16: 3 | S16: =ROUND((M16*R16),1) -> 24 | T16: =U16/S16 -> 1 | U16: =SUM(W16:AO16) -> 24 | W16: 24
C17: Direcionar os integrantes a seus objetivos. | D17: Estruturar as ideias do projeto. | E17: Ter uma lógistica de tarefas fácil de se gerir. | F17: Sala de aula C13. | G17: Todos os integrantes do grupo | H17: Através de um brainstorm de todos os integrantes que irá ser registrado na TAP no projeto | I17: 44425 | J17: 2 | K17: 4 | L17: 6 | M17: =(J17+(4*K17)+L17)/6 -> 4 | N17: =SUM($S$93:$S$96)*M17 -> 404.6 | R17: 2 | S17: =ROUND((M17*R17),1) -> 8 | T17: =U17/S17 -> 1 | U17: =SUM(W17:AO17) -> 8 | W17: 4 | X17: 4
C18: Facilitar o reconhecimento das limitações e acrecismos dos integrantes do Projeto. | D18: verificar as forças e fraquezas de todos os integrantes do grupo. | E18: Facilitar na atribuição de tarefas de todos os integrantes do grupo. | F18: Sala de aula C13. | G18: Todos os integrantes do grupo | H18: Através de um brainstorm de todos os integrantes que irá ser registrado na TAP no projeto | I18: 44421 | J18: 2 | K18: 4 | L18: 6 | M18: =(J18+(4*K18)+L18)/6 -> 4 | N18: =SUM($S$93:$S$96)*M18 -> 404.6 | R18: 2 | S18: =ROUND((M18*R18),1) -> 8 | T18: =U18/S18 -> 1 | U18: =SUM(W18:AO18) -> 8 | W18: 8
C19: Atribuição de reponsabilidades de integrantes especificos em determinadas temas. | D19: Atribuir responsabilidades a todos os integrantes do grupo. | E19: Agilizar a realização do projeto. | F19: Sala de aula C08 | G19: Todos os integrantes do grupo | H19: Através de um brainstorm de todos os integrantes que irá ser registrado na TAP no projeto | I19: 44427 | J19: 1 | K19: 3 | L19: 5 | M19: =(J19+(4*K19)+L19)/6 -> 3 | N19: =SUM($S$93:$S$96)*M19 -> 303.45 | R19: 2 | S19: =ROUND((M19*R19),1) -> 6 | T19: =U19/S19 -> 1 | U19: =SUM(W19:AO19) -> 6 | W19: 6
C20: Gerar um aprimoramento no que já foi realizado. | D20: Revisar o trabalho. | E20: Corrigir possiveis erros gramáticais. | F20: Sala de aula C08 | G20: Todos os integrantes do grupo | H20: Consultando integrantes do grupo e professores. | I20: 44432 | J20: 2 | K20: 4 | L20: 6 | M20: =(J20+(4*K20)+L20)/6 -> 4 | N20: =SUM($S$93:$S$96)*M20 -> 404.6 | R20: 1 | S20: =ROUND((M20*R20),1) -> 4 | T20: =U20/S20 -> 1 | U20: =SUM(W20:AO20) -> 4 | X20: 3 | Y20: 1
C21: Cumprir com os criterios passados em sala de aula e do PMBOK. | D21: Validação. | E21: Fazer uma segunda revisão para verificar possiveis erros. | F21: Sala de aula C08 | G21: Todos os integrantes do grupo | H21: Consultando professores | I21: 44434 | J21: 2 | K21: 4 | L21: 6 | M21: =(J21+(4*K21)+L21)/6 -> 4 | N21: =SUM($S$93:$S$96)*M21 -> 404.6 | R21: 2 | S21: =ROUND((M21*R21),1) -> 8 | T21: =U21/S21 -> 1 | U21: =SUM(W21:AO21) -> 8 | X21: 4 | Y21: 4
B22: Escopo | C22: Definir e separar as principais renponsabilidades em etapas. | D22: Definir como e quando serão realizadas as atividas e etapas do projeto. | E22: Facilitar a gestão do projeto. | F22: Sala de aula C08 | G22: Todos os integrantes do grupo | H22: Através de um brainstrom entre os integrantes do grupo e usando uma planilha do excel definimos as etapas do projeto | I22: 44432 | J22: 2 | K22: 4 | L22: 6 | M22: =(J22+(4*K22)+L22)/6 -> 4 | N22: =SUM($S$93:$S$96)*M22 -> 404.6 | R22: 1 | S22: =ROUND((M22*R22),1) -> 4 | T22: =U22/S22 -> 1 | U22: =SUM(W22:AO22) -> 4 | X22: 1 | Y22: 2 | Z22: 1
C23: Desmembrar as etapas em tarefas. | D23: Dividir o projeto em partes. | E23: Facilitar na gestão do projeto | F23: Sala de aula C08 | G23: Todos os integrantes do grupo | H23: Através de um brainstrom entre os integrantes do grupo nos definimos onde cada tarefa se alocará | I23: 44432 | J23: 3 | K23: 6 | L23: 15 | M23: =(J23+(4*K23)+L23)/6 -> 7 | N23: =SUM($S$93:$S$96)*M23 -> 708.05 | R23: 1 | S23: =ROUND((M23*R23),1) -> 7 | T23: =U23/S23 -> 1 | U23: =SUM(W23:AO23) -> 7 | X23: 1 | Y23: 3 | Z23: 3
C24: Direcionar de maneira mais profundada a todos os processos do projeto. | D24: Descrever as tarefas a serem executadas pelos integrantes baseado na análise SWOT e RACI. | E24: Facilitar na gestão do projeto e trazer mais facilidade no desenvolvimento do projeto. | F24: Sala de aula C08 | G24: Todos os integrantes do grupo | H24: Através de uma divisão dos integrantes nos montamos o dicionário da EAP usando e software da microsoft Excel. | I24: 44434 | J24: 6 | K24: 8 | L24: 16 | M24: =(J24+(4*K24)+L24)/6 -> 9 | N24: =SUM($S$93:$S$96)*M24 -> 910.35 | R24: 1 | S24: =ROUND((M24*R24),1) -> 9 | T24: =U24/S24 -> 1 | U24: =SUM(W24:AO24) -> 9 | X24: 2 | Y24: 2 | Z24: 5
C25: Gerar um aprimoramento naquilo que já foi executado. | D25: Revisar o que se foi realizado. | E25: verificar se o que foi feito está como planejado e sugerir possiveis melhorias. | F25: Sala de aula C08 | G25: Todos os integrantes do grupo | H25: Uma leitura da TAP pelo lider e vice-lider | I25: 44439 | J25: 4 | K25: 9 | L25: 20 | M25: =(J25+(4*K25)+L25)/6 -> 10 | N25: =SUM($S$93:$S$96)*M25 -> 1011.5 | R25: 1 | S25: =ROUND((M25*R25),1) -> 10 | T25: =U25/S25 -> 1 | U25: =SUM(W25:AO25) -> 10 | Y25: 4 | Z25: 4 | AA25: 2
C26: Cumprir com os criterios passados em sala de aula e do PMBOK. | D26: validar o trabalho que foi feito nessa etapa | E26: Verificar se o que foi feito está como planejado. | F26: Sala de aula C08 | G26: Todos os integrantes do grupo | H26: Uma leitura da TAP pelo lider e vice-lider | I26: 44439 | J26: 3 | K26: 6 | L26: 9 | M26: =(J26+(4*K26)+L26)/6 -> 6 | N26: =SUM(S103:S106)*M26 -> 0 | R26: 3 | S26: =ROUND((M26*R26),1) -> 18 | T26: =U26/S26 -> 1 | U26: =SUM(W26:AO26) -> 18 | Y26: 10 | Z26: 5 | AA26: 3
B27: Cronograma | C27: Finalidade do Projeto, a meta final. | D27: Análisar o escopo | E27: Criar um sentimento de responsabilidade para cada integrante do grupo com a tarefa atribuida a ele. | F27: C13 | G27: Leandro Costa Petrick Gomes | H27: Através de uma conversa entre os integrantes nos iremos revisar as divições das tarefas | I27: 44441 | J27: 2 | K27: 3 | L27: 6 | M27: =(J27+(4*K27)+L27)/6 -> 3.3333333 | N27: =SUM(S93+S94)*M27 -> 240 | R27: 3 | S27: =ROUND((M27*R27),1) -> 10 | T27: =U27/S27 -> 1 | U27: =SUM(W27:AO27) -> 10 | Y27: 5 | Z27: 5
C28: Levar um tempo de trabalho necessario e esperado. | D28: Definir o tempo para realizar cada etapa. | E28: Permitir que o projeto seja entregue a tempo. | F28: C13 | G28: Leandro Costa Petrick Gomes | H28: Através da formula de PER, usando o software Excel e uma brainstorm com todos os integrantes definimos as tarefas a serem realizadas. | I28: 44447 | J28: 5 | K28: 7 | L28: 11 | M28: =(J28+(4*K28)+L28)/6 -> 7.3333333 | N28: =SUM($S$94+$S$95)*M28 -> 298.46667 | R28: 3 | S28: =ROUND((M28*R28),1) -> 22 | T28: =U28/S28 -> 1 | U28: =SUM(W28:AO28) -> 22 | Z28: 4 | AA28: 4 | AB28: 14
C29: Levar uma elaboração antecipada. | D29: Definir datas para a entrega de cada etapa do projeto. | E29: Facilitar na gestão do projeto. | F29: C13 | G29: Leandro Costa Petrick Gomes | H29: Através da formula de PER, usando o software Excel e uma brainstorm de todos os integrantes definimos as tarefas a serem realizadas. | I29: 44448 | J29: 4 | K29: 6 | L29: 12 | M29: =(J29+(4*K29)+L29)/6 -> 6.6666667 | N29: =SUM($S$94+$S$95)*M29 -> 271.33333 | R29: 3 | S29: =ROUND((M29*R29),1) -> 20 | T29: =U29/S29 -> 1 | U29: =SUM(W29:AO29) -> 20 | Z29: 4 | AA29: 4 | AB29: 12
C30: Gerar um aprimoramento naquilo que já foi executado. | D30: Revisar o que ja foi realizado. | E30: Sujerir posiveis melhorias e evitar possiveis erros. | F30: C13 | G30: Leandro Costa Petrick Gomes | H30: Uma leitura da TAP pelo lider e vice-lider | I30: 44449 | J30: 2 | K30: 3 | L30: 7 | M30: =(J30+(4*K30)+L30)/6 -> 3.5 | N30: =SUM($S$94+$S$95)*M30 -> 142.45 | R30: 2 | S30: =ROUND((M30*R30),1) -> 7 | T30: =U30/S30 -> 1 | U30: =SUM(W30:AO30) -> 7 | AA30: 1 | AB30: 6
C31: Cumprir com os criterios passados em aula e do PMBOK. | D31: validar o que ja foi realizado. | E31: Sujerir posiveis melhorias e evitar possiveis erros | F31: C13 | G31: Leandro Costa Petrick Gomes | H31: Uma leitura da TAP pelo lider e vice-lider | I31: 44449 | J31: 2 | K31: 3 | L31: 6 | M31: =(J31+(4*K31)+L31)/6 -> 3.3333333 | N31: =SUM($S$94+$S$95)*M31 -> 135.66667 | R31: 3 | S31: =ROUND((M31*R31),1) -> 10 | T31: =U31/S31 -> 1 | U31: =SUM(W31:AO31) -> 10 | AA31: 1 | AB31: 9
B32: Analises de Risco do Projeto | C32: Levantar os possiveis riscos. | D32: Avaliar os possíveis riscos do projeto. | E32: Evitar/ amenizar os riscos ao projeto. | F32: C13 | G32: Cosme Sousa Damião Sousa | H32: Através de um brainstorm de todos os responsaveis iremos abordar possiveis estratégias para evitar os riscos. | I32: 44453 | J32: 4 | K32: 6 | L32: 8 | M32: =(J32+(4*K32)+L32)/6 -> 6 | N32: =($S$95+$S$96)*M32 -> 174.9 | R32: 2 | S32: =ROUND((M32*R32),1) -> 12 | T32: =U32/S32 -> 1 | U32: =SUM(W32:AO32) -> 12 | AA32: 5 | AB32: 7
C33: Preparar-se sob a probabilidade dos riscos. | D33: Avaliar a probabilidade dos riscos acontecerem. | E33: Fazer preparações de acordo com o nivel de probabilidade. | F33: C13 | G33: Cosme Sousa Damião Sousa | H33: Através de um brainstorm de todos os responsaveis considerar quais os riscos mais prováveis. | I33: 44455 | J33: 4 | K33: 6 | L33: 8 | M33: =(J33+(4*K33)+L33)/6 -> 6 | N33: =($S$95+$S$96)*M33 -> 174.9 | R33: 2 | S33: =ROUND((M33*R33),1) -> 12 | T33: =U33/S33 -> 1 | U33: =SUM(W33:AO33) -> 12 | AA33: 12
C34: Gerar possiveis consequências. | D34: Definir o quão grave é o risco e as medidas de supressão dele. | E34: Definir o que será feito, caso algum risco venha acontecer. | F34: C13 | G34: Cosme Sousa Damião Sousa | H34: Através de um brainstorm de todos os responsaveis iremos abordar possiveis estratégias para evitar os riscos. | I34: 44455 | J34: 4 | K34: 6 | L34: 8 | M34: =(J34+(4*K34)+L34)/6 -> 6 | N34: =($S$95+$S$96)*M34 -> 174.9 | R34: 3 | S34: =ROUND((M34*R34),1) -> 18 | T34: =U34/S34 -> 1 | U34: =SUM(W34:AO34) -> 18 | AA34: 18
C35: Comparar o tempo de trabalho com a meta. | D35: Fazer um gráfico de acompanhamento do trabalho. | E35: Avaliar o desenvolvimento do projeto e analisar se está caminhando de acordo com o planejado, para poder gerar uma possivel data de entrega. | F35: C13 | G35: Cosme Sousa Damião Sousa | H35: Através da formula de PER iremos desenvolver quanto tempo é necessário para a execução de cada tarefa do projeto e com essa informação iremos estimar uma valor em pontos para cada atividade que por fim será usado no gráfico do burndown chart juntamente com o tempo disponivel. | I35: 44455 | J35: 4 | K35: 6 | L35: 8 | M35: =(J35+(4*K35)+L35)/6 -> 6 | N35: =($S$95+$S$96)*M35 -> 174.9 | R35: 3 | S35: =ROUND((M35*R35),1) -> 18 | T35: =U35/S35 -> 1 | U35: =SUM(W35:AO35) -> 18 | AA35: 18
A36: INSTALAÇÃO | B36: Painéis | C36: Permitir que todos os quadros de energia possam ser instalados dentro do quadro de distribuição | D36: Usar a escala de mm para definir o tamanho do quadro de distribuição que conterá os quadros de iluminação, CFTV e alarme de incêndio. | E36: Para trazer uma sensação visual melhor, evitar gastos desnecessários e facilitar possiveis aprimoramentos da instalação. | F36: oficina IELI 1 | G36: Leandro Costa João Miranda | H36: Através de um técnico altamente treinado irá ser feito um dimenciosamento do sistema elétrico da instalação e com essa insformação iremos definir a quantidade de componentes necessarios para a instalação e assim a dimenção do quadro | I36: 44459 | J36: 4 | K36: 5 | L36: 8 | M36: =(J36+(4*K36)+L36)/6 -> 5.3333333 | N36: =($S$95+$S$96)*M36 -> 155.46667 | R36: 3 | S36: =ROUND((M36*R36),1) -> 16 | T36: =U36/S36 -> 1 | U36: =SUM(W36:AO36) -> 16 | AB36: 10 | AC36: 3 | AD36: 3
C37: Proteção de todos os circuitos da residência, seguindo a norma NR10. | D37: Usar dispositivos de proteção como: DR e DPS para a proteção dos circuitos. | E37: proteger o circuito. | F37: oficina IELI 1 | G37: Leandro Costa João Miranda | H37: Usando os conhecimento adquiridos pelo curso de eletroeletrônica do SENAI, iremos dimencionar o quadro de força | I37: 44459 | J37: 4 | K37: 5 | L37: 8 | M37: =(J37+(4*K37)+L37)/6 -> 5.3333333 | N37: =($S$95+$S$96)*M37 -> 155.46667 | R37: 3 | S37: =ROUND((M37*R37),1) -> 16 | T37: =U37/S37 -> 1 | U37: =SUM(W37:AO37) -> 16 | AB37: 13 | AC37: 3
B38: Instalação do CFTV | C38: Fazer a alimentação das câmeras e do DRV com condutores isolados e sem imendas nos eletrodutos. | D38: Passar os cabos pelos eletrodutos. | E38: Permitir a alimentação dos componentes. | F38: oficina IELI 1 | G38: Pétrick Gomes Cosme Sousa Damião Sousa Nilton Guerra | H38: Fazer o dimensionamento dos cabos para a instalação das câmeras | I38: 44461 | J38: 4 | K38: 5 | L38: 10 | M38: 1 | N38: =$S$95+(4*$S$96)*M38 -> 60.5 | R38: 3 | S38: =ROUND((M38*R38),1) -> 3 | T38: =U38/S38 -> 1 | U38: =SUM(W38:AO38) -> 3 | AB38: 3
C39: Fixar as câmeras e fazer a alimentação e a transmição de dados com facilidade. | D39: Instalar apoios para as câmeras através de parafusos e porcas, para logo em seguida colocar as câmeras. | E39: Para permitir a monitoração de locais previamentes desiginados. | F39: oficina IELI 1 | G39: Pétrick Gomes Cosme Sousa Damião Sousa Nilton Guerra | H39: definir posição para instalação das câmeras | I39: 44462 | J39: 2 | K39: 4 | L39: 6 | M39: 1 | N39: =$S$95+(4*$S$96)*M39 -> 60.5 | R39: 2 | S39: =ROUND((M39*R39),1) -> 2 | T39: =U39/S39 -> 1 | U39: =SUM(W39:AO39) -> 2 | AB39: 2
C40: Permitir a comunicação do monitor com o DRV | D40: usar o cabo VGA para comunicar o DVR com o monitor e alimentar ambos. | E40: Para permitir o acompanhamneto da vigilância dos locais pelo monitor. | F40: oficina IELI 1 | G40: Pétrick Gomes Cosme Sousa Damião Sousa Nilton Guerra | H40: Interligação do DVR com o monitor | I40: 44462 | J40: 2 | K40: 4 | L40: 6 | M40: 1 | N40: =$S$95+(4*$S$96)*M40 -> 60.5 | R40: 2 | S40: =ROUND((M40*R40),1) -> 2 | T40: =U40/S40 -> 1 | U40: =SUM(W40:AO40) -> 2 | AB40: 2
C41: Permitir a visualização dos pontos de vigilância no monitor | D41: usando o conector P4 macho e fêmea e o cabo coaxial fazer o interligamento da câmera com o DVR. | E41: Comunicar o DVR com as câmeras. | F41: oficina IELI 1 | G41: Pétrick Gomes Cosme Sousa Damião Sousa Nilton Guerra | H41: Interligação das câmeras com Central para ser feito monitoriamento com DVR | I41: 44462 | J41: 2 | K41: 4 | L41: 6 | M41: 1 | N41: =$S$95+(4*$S$96)*M41 -> 60.5 | R41: 3 | S41: =ROUND((M41*R41),1) -> 3 | T41: =U41/S41 -> 1 | U41: =SUM(W41:AO41) -> 3 | AB41: 3
B42: Instalação da central | C42: Que os cabos passados sejam alimentados e devidamente isolados sem imentas nos eletrodutos. | D42: Passar os cabos pelos eletrodutos. | E42: Permitir a alimentação dos componentes | F42: oficina IELI 1 | G42: Cosme Sousa Damião Sousa Pétrick Gomes Nilton Guerra | H42: Usando um guia passa fio iremos direcionar os cabos para suas devidas posições já estipuladas no planejamento. | I42: 44463 | J42: 2 | K42: 4 | L42: 6 | M42: 1 | N42: =$S$95+(4*$S$96)*M42 -> 60.5 | R42: 2 | S42: =ROUND((M42*R42),1) -> 2 | T42: =U42/S42 -> 1 | U42: =SUM(W42:AO42) -> 2 | AC42: 2
C43: Ligar todas as conexões dos sensores corretamente. | D43: Instalar os sensores de fumaça respeitando as suas coneções com a central de incêndio. | E43: Permitir que o sensor funcione corretamente. | F43: oficina IELI 1 | G43: Cosme Sousa Damião Sousa Pétrick Gomes Nilton Guerra | H43: Usando a escada e uma chave de fenda iremos instalar os sensores de fumaça respeitando a posição de cada cabo. | I43: 44463 | J43: 4 | K43: 6 | L43: 8 | M43: 1 | N43: =$S$95+(4*$S$96)*M43 -> 60.5 | R43: 3 | S43: =ROUND((M43*R43),1) -> 3 | T43: =U43/S43 -> 1 | U43: =SUM(W43:AO43) -> 3 | AC43: 3
C44: Fazer a comunicação entre central de alarme de incêndio e sensores de fumaça. | D44: Posicionar a centrtal em um local especifico para gerenciar o controle de incêndio. | E44: Ter um controle mais rápido e eficiente do sistema de incêndio | F44: oficina IELI 1 | G44: Cosme Sousa Damião Sousa Pétrick Gomes Nilton Guerra | H44: definir uma posição para a central de incêndio que não incomode ninguém | I44: 44466 | J44: 4 | K44: 6 | L44: 8 | M44: 1 | N44: =$S$95+(4*$S$96)*M44 -> 60.5 | R44: 2 | S44: =ROUND((M44*R44),1) -> 2 | T44: =U44/S44 -> 1 | U44: =SUM(W44:AO44) -> 2 | AB44: 2
B45: Instalação de Iluminação | C45: Que os cabos passados sejam alimentados e devidamente isolados sem emendas nos eletrodutos. | D45: Passar os cabos pelos eletrodutos. | E45: Permitir a alimentação dos componentes | F45: oficina IELI 1 | G45: Cosme Sousa Damião Sousa Pétrick Gomes Leandro Costa | H45: Usando um passa fio iremos direcionar os cabos para suas devidas posições já estipuladas no planejamento. | I45: 44474 | J45: 2 | K45: 5 | L45: 8 | M45: 6 | N45: =$S$95+(4*$S$96)*M45 -> 269.5 | R45: 2 | S45: =ROUND((M45*R45),1) -> 12 | T45: =U45/S45 -> 1 | U45: =SUM(W45:AO45) -> 12 | AD45: 5 | AE45: 5 | AF45: 2
...

Sheet Checklist
B2: PROJETO AUTOMOÇÃO PREDIAL | C2: Lista de Conteudos e Apresentações | K2: A Fazer | L2: =COUNTIF(A4:A77,"FALSO") -> 0 | M2: =L2/COUNTA(F4:F77) -> 0
C3: Tema | E3: Data | F3: Estado | H3: Revisão | I3: Notas | K3: Feito | L3: =COUNTIF(A4:A77,TRUE) -> 20 | M3: =L3/COUNTA(A4:A22) -> 1.0526316
A4: TRUE | D4: ='Dicionario EAP2'!C16 -> Especificar o objetivo central do projeto. | E4: ='Dicionario EAP2'!I16 -> 44421 | F4: =IF(A4=FALSE,"A Fazer","Feito") -> Feito | H4: =IF(J4=FALSE,"Pendente","Revisado") -> Pendente | J4: FALSE
A5: TRUE | D5: ='Dicionario EAP2'!C17 -> Direcionar os integrantes a seus objetivos. | E5: ='Dicionario EAP2'!I17 -> 44425 | F5: =IF(A5=FALSE,"A Fazer","Feito") -> Feito | H5: =IF(J5=FALSE,"Pendente","Revisado") -> Revisado | J5: TRUE
A6: TRUE | D6: ='Dicionario EAP2'!C18 -> Facilitar o reconhecimento das limitações e acrecismos dos integrantes do Projeto. | E6: ='Dicionario EAP2'!I18 -> 44421 | F6: =IF(A6=FALSE,"A Fazer","Feito") -> Feito | H6: =IF(J6=FALSE,"Pendente","Revisado") -> Pendente | J6: FALSE
A7: TRUE | D7: ='Dicionario EAP2'!C19 -> Atribuição de reponsabilidades de integrantes especificos em determinadas temas. | E7: ='Dicionario EAP2'!I19 -> 44427 | F7: =IF(A7=FALSE,"A Fazer","Feito") -> Feito | H7: =IF(J7=FALSE,"Pendente","Revisado") -> Pendente | J7: FALSE
A8: TRUE | D8: ='Dicionario EAP2'!C20 -> Gerar um aprimoramento no que já foi realizado. | E8: ='Dicionario EAP2'!I20 -> 44432 | F8: =IF(A8=FALSE,"A Fazer","Feito") -> Feito | H8: =IF(J8=FALSE,"Pendente","Revisado") -> Pendente | J8: FALSE
A9: TRUE | D9: ='Dicionario EAP2'!C21 -> Cumprir com os criterios passados em sala de aula e do PMBOK. | E9: ='Dicionario EAP2'!I21 -> 44434 | F9: =IF(A9=FALSE,"A Fazer","Feito") -> Feito | H9: =IF(J9=FALSE,"Pendente","Revisado") -> Pendente | J9: FALSE
A10: TRUE | D10: ='Dicionario EAP2'!C22 -> Definir e separar as principais renponsabilidades em etapas. | E10: ='Dicionario EAP2'!I22 -> 44432 | F10: =IF(A10=FALSE,"A Fazer","Feito") -> Feito | H10: =IF(J10=FALSE,"Pendente","Revisado") -> Pendente | J10: FALSE
A11: TRUE | D11: ='Dicionario EAP2'!C23 -> Desmembrar as etapas em tarefas. | E11: ='Dicionario EAP2'!I23 -> 44432 | F11: =IF(A11=FALSE,"A Fazer","Feito") -> Feito | H11: =IF(J11=FALSE,"Pendente","Revisado") -> Pendente | J11: FALSE
A12: TRUE | D12: ='Dicionario EAP2'!C24 -> Direcionar de maneira mais profundada a todos os processos do projeto. | E12: ='Dicionario EAP2'!I24 -> 44434 | F12: =IF(A12=FALSE,"A Fazer","Feito") -> Feito | H12: =IF(J12=FALSE,"Pendente","Revisado") -> Pendente | J12: FALSE
A13: TRUE | D13: ='Dicionario EAP2'!C25 -> Gerar um aprimoramento naquilo que já foi executado. | E13: ='Dicionario EAP2'!I25 -> 44439 | F13: =IF(A13=FALSE,"A Fazer","Feito") -> Feito | H13: =IF(J13=FALSE,"Pendente","Revisado") -> Pendente | J13: FALSE
A14: TRUE | D14: ='Dicionario EAP2'!C26 -> Cumprir com os criterios passados em sala de aula e do PMBOK. | E14: ='Dicionario EAP2'!I26 -> 44439 | F14: =IF(A14=FALSE,"A Fazer","Feito") -> Feito | H14: =IF(J14=FALSE,"Pendente","Revisado") -> Pendente | J14: FALSE
A15: TRUE | D15: ='Dicionario EAP2'!C27 -> Finalidade do Projeto, a meta final. | E15: ='Dicionario EAP2'!I27 -> 44441 | F15: =IF(A15=FALSE,"A Fazer","Feito") -> Feito | H15: =IF(J15=FALSE,"Pendente","Revisado") -> Pendente | J15: FALSE | K15: Pendente | L15: =COUNTIF(J4:J22,"FALSO") -> 17 | M15: =L15/COUNTA(H4:H22) -> 0.89473684
A16: TRUE | D16: ='Dicionario EAP2'!C28 -> Levar um tempo de trabalho necessario e esperado. | E16: ='Dicionario EAP2'!I28 -> 44447 | F16: =IF(A16=FALSE,"A Fazer","Feito") -> Feito | H16: =IF(J16=FALSE,"Pendente","Revisado") -> Pendente | J16: FALSE | K16: Revisado | L16: =COUNTIF(J4:J22,TRUE) -> 2 | M16: =L16/COUNTA(H4:H22) -> 0.10526316
A17: TRUE | D17: ='Dicionario EAP2'!C29 -> Levar uma elaboração antecipada. | E17: ='Dicionario EAP2'!I29 -> 44448 | F17: =IF(A17=FALSE,"A Fazer","Feito") -> Feito | H17: =IF(J17=FALSE,"Pendente","Revisado") -> Pendente | J17: FALSE
A18: TRUE | D18: ='Dicionario EAP2'!C30 -> Gerar um aprimoramento naquilo que já foi executado. | E18: ='Dicionario EAP2'!I30 -> 44449 | F18: =IF(A18=FALSE,"A Fazer","Feito") -> Feito | H18: =IF(J18=FALSE,"Pendente","Revisado") -> Pendente | J18: FALSE
A19: TRUE | D19: ='Dicionario EAP2'!C31 -> Cumprir com os criterios passados em aula e do PMBOK. | E19: ='Dicionario EAP2'!I31 -> 44449 | F19: =IF(A19=FALSE,"A Fazer","Feito") -> Feito | H19: =IF(J19=FALSE,"Pendente","Revisado") -> Pendente | J19: FALSE
A20: TRUE | D20: ='Dicionario EAP2'!C32 -> Levantar os possiveis riscos. | E20: ='Dicionario EAP2'!I32 -> 44453 | F20: =IF(A20=FALSE,"A Fazer","Feito") -> Feito | H20: =IF(J20=FALSE,"Pendente","Revisado") -> Pendente | J20: FALSE
A21: TRUE | D21: ='Dicionario EAP2'!C33 -> Preparar-se sob a probabilidade dos riscos. | E21: ='Dicionario EAP2'!I33 -> 44455 | F21: =IF(A21=FALSE,"A Fazer","Feito") -> Feito | H21: =IF(J21=FALSE,"Pendente","Revisado") -> Pendente | J21: FALSE
A22: TRUE | D22: ='Dicionario EAP2'!C34 -> Gerar possiveis consequências. | E22: ='Dicionario EAP2'!I34 -> 44455 | F22: =IF(A22=FALSE,"A Fazer","Feito") -> Feito | H22: =IF(J22=FALSE,"Pendente","Revisado") -> Revisado | J22: TRUE
A23: TRUE | D23: ='Dicionario EAP2'!C35 -> Comparar o tempo de trabalho com a meta. | E23: ='Dicionario EAP2'!I35 -> 44455 | F23: =IF(A23=FALSE,"A Fazer","Feito") -> Feito | H23: =IF(J23=FALSE,"Pendente","Revisado") -> Revisado | J23: TRUE
D24: ='Dicionario EAP2'!C36 -> Permitir que todos os quadros de energia possam ser instalados dentro do quadro de distribuição | E24: ='Dicionario EAP2'!I36 -> 44459 | F24: =IF(A24=FALSE,"A Fazer","Feito") -> A Fazer | H24: =IF(J24=FALSE,"Pendente","Revisado") -> Revisado | J24: TRUE
D25: ='Dicionario EAP2'!C37 -> Proteção de todos os circuitos da residência, seguindo a norma NR10. | E25: ='Dicionario EAP2'!I37 -> 44459 | F25: =IF(A25=FALSE,"A Fazer","Feito") -> A Fazer | H25: =IF(J25=FALSE,"Pendente","Revisado") -> Pendente | J25: FALSE
D26: ='Dicionario EAP2'!C38 -> Fazer a alimentação das câmeras e do DRV com condutores isolados e sem imendas nos eletrodutos. | E26: ='Dicionario EAP2'!I38 -> 44461 | F26: =IF(A26=FALSE,"A Fazer","Feito") -> A Fazer | H26: =IF(J26=FALSE,"Pendente","Revisado") -> Revisado | J26: TRUE
D27: ='Dicionario EAP2'!C39 -> Fixar as câmeras e fazer a alimentação e a transmição de dados com facilidade. | E27: ='Dicionario EAP2'!I39 -> 44462 | F27: =IF(A27=FALSE,"A Fazer","Feito") -> A Fazer | H27: =IF(J27=FALSE,"Pendente","Revisado") -> Revisado | J27: TRUE
D28: ='Dicionario EAP2'!C40 -> Permitir a comunicação do monitor com o DRV | E28: ='Dicionario EAP2'!I40 -> 44462 | F28: =IF(A28=FALSE,"A Fazer","Feito") -> A Fazer | H28: =IF(J28=FALSE,"Pendente","Revisado") -> Revisado | J28: TRUE
D29: ='Dicionario EAP2'!C41 -> Permitir a visualização dos pontos de vigilância no monitor | E29: ='Dicionario EAP2'!I41 -> 44462 | F29: =IF(A29=FALSE,"A Fazer","Feito") -> A Fazer | H29: =IF(J29=FALSE,"Pendente","Revisado") -> Revisado | J29: TRUE
D30: ='Dicionario EAP2'!C42 -> Que os cabos passados sejam alimentados e devidamente isolados sem imentas nos eletrodutos. | E30: ='Dicionario EAP2'!I42 -> 44463 | F30: =IF(A30=FALSE,"A Fazer","Feito") -> A Fazer | H30: =IF(J30=FALSE,"Pendente","Revisado") -> Revisado | J30: TRUE
D31: ='Dicionario EAP2'!C43 -> Ligar todas as conexões dos sensores corretamente. | E31: ='Dicionario EAP2'!I43 -> 44463 | F31: =IF(A31=FALSE,"A Fazer","Feito") -> A Fazer | H31: =IF(J31=FALSE,"Pendente","Revisado") -> Revisado | J31: TRUE
D32: ='Dicionario EAP2'!C44 -> Fazer a comunicação entre central de alarme de incêndio e sensores de fumaça. | E32: ='Dicionario EAP2'!I44 -> 44466 | F32: =IF(A32=FALSE,"A Fazer","Feito") -> A Fazer | H32: =IF(J32=FALSE,"Pendente","Revisado") -> Revisado | J32: TRUE
D33: ='Dicionario EAP2'!C45 -> Que os cabos passados sejam alimentados e devidamente isolados sem emendas nos eletrodutos. | E33: ='Dicionario EAP2'!I45 -> 44474 | F33: =IF(A33=FALSE,"A Fazer","Feito") -> A Fazer | H33: =IF(J33=FALSE,"Pendente","Revisado") -> Revisado | J33: TRUE
D34: ='Dicionario EAP2'!C46 -> Fazer a instalação dos interruptores e lâmpadas | E34: ='Dicionario EAP2'!I46 -> 44476 | F34: =IF(A34=FALSE,"A Fazer","Feito") -> A Fazer | H34: =IF(J34=FALSE,"Pendente","Revisado") -> Revisado | J34: TRUE
D35: ='Dicionario EAP2'!C47 -> fazer a integração dos sistema de iluminação com os aplicativos (bluelux,sonoff). | E35: ='Dicionario EAP2'!I47 -> 44477 | F35: =IF(A35=FALSE,"A Fazer","Feito") -> A Fazer | H35: =IF(J35=FALSE,"Pendente","Revisado") -> Revisado | J35: TRUE
... D39: ='Dicionario EAP2'!C51 -> Verificar se o monitor de energia está funcionando corretamente. | E39: ='Dicionario EAP2'!I51 -> 44493 | F39: =IF(A39=FALSE,"A Fazer","Feito") -> A Fazer | H39: =IF(J39=FALSE,"Pendente","Revisado") -> Revisado | J39: TRUE
D40: ='Dicionario EAP2'!C52 -> Controlar alexa pelo app. | E40: ='Dicionario EAP2'!I53 -> 44497 | F40: =IF(A40=FALSE,"A Fazer","Feito") -> A Fazer | H40: =IF(J40=FALSE,"Pendente","Revisado") -> Revisado | J40: TRUE
D41: ='Dicionario EAP2'!C53 -> Alexa Responder aos comandos corretamente. | E41: ='Dicionario EAP2'!#REF! -> #REF! | F41: =IF(A41=FALSE,"A Fazer","Feito") -> A Fazer | H41: =IF(J41=FALSE,"Pendente","Revisado") -> Revisado | J41: TRUE
D42: ='Dicionario EAP2'!C54 -> Alexa controlar outros dispositivos. | E42: ='Dicionario EAP2'!I54 -> 44504 | F42: =IF(A42=FALSE,"A Fazer","Feito") -> A Fazer | H42: =IF(J42=FALSE,"Pendente","Revisado") -> Revisado | J42: TRUE
D43: ='Dicionario EAP2'!C55 -> Interfone estar fixado. | E43: ='Dicionario EAP2'!I55 -> 44469 | F43: =IF(A43=FALSE,"A Fazer","Feito") -> A Fazer | H43: =IF(J43=FALSE,"Pendente","Revisado") -> Revisado | J43: TRUE
D44: ='Dicionario EAP2'!C56 -> Verificar o funcionando do interfone | E44: ='Dicionario EAP2'!I56 -> 44470 | F44: =IF(A44=FALSE,"A Fazer","Feito") -> A Fazer | H44: =IF(J44=FALSE,"Pendente","Revisado") -> Revisado | J44: TRUE
...

Sheet Grafico Gantt 
B1: Automação Predial | I1: Legenda:
I2: Baixo risco | N2: Médio risco | S2: Alto risco
B3: Leandro Costa Fereira | D3: Data de início do projeto: | F3: 44420 | H3: PESO: | I3: 1 | N3: 2 | S3: 3
D4: Incremento de rolagem: | F4: 44 | I4: =TEXT(I5,"mmmm") -> setembro
I5: =IFERROR(Início_do_projeto+Incremento_de_rolagem,TODAY()) -> 44464 | J5: =I5+1 -> 44465 | K5: =J5+1 -> 44466 | L5: =K5+1 -> 44467 | M5: =L5+1 -> 44468 | N5: =M5+1 -> 44469 | O5: =N5+1 -> 44470 | P5: =O5+1 -> 44471 | Q5: =P5+1 -> 44472 | ... BL5: =BK5+1 -> 44519
A6: A barra de rolagem está nas células I6 a BL6. O incremento para percorrer os dados está definido como duas páginas por vez e pode ser ajustado nas configurações da barra de controle. Para ir para a frente ou para trás na linha do tempo, insira um valor de 0 ou mais na célula F4. O valor 0 leva você ao início do gráfico.
A7: Etapas | B7: Descrição do marco | C7: Risco | D7: Atribuído a | E7: Progresso | F7: Início | G7: Nº de dias | I7: =LEFT(TEXT(I5,"ddd"),3) -> sáb | J7: =LEFT(TEXT(J5,"ddd"),3) -> dom | K7: =LEFT(TEXT(K5,"ddd"),3) -> seg | L7: =LEFT(TEXT(L5,"ddd"),3) -> ter | M7: =LEFT(TEXT(M5,"ddd"),3) -> qua | N7: =LEFT(TEXT(N5,"ddd"),3) -> qui | O7: =LEFT(TEXT(O5,"ddd"),3) -> sex | P7: =LEFT(TEXT(P5,"ddd"),3) -> sáb | ... BL7: =LEFT(TEXT(BL5,"ddd"),3) -> sex
A8: Não exclua esta planilha. Esta linha ficará oculta para preservar uma fórmula usada para realçar o dia atual no cronograma do projeto.
A9: Especificar o objetivo central do projeto. | B9: Formalizar o projeto e as obrigações de todos os integrantes. | C9: Alto risco | D9: ='Dicionario EAP2'!G16 -> equipe | E9: ='Dicionario EAP2'!T16 -> 1 | F9: ='Dicionario EAP2'!I16 -> 44421 | G9: 5 | I9: =IF(AND($C9="Objetivo",I$5>=$F9,I$5<=$F9+$G9-1),2,IF(AND($C9="Marco",I$5>=$F9,I$5<=$F9+$G9-1),1,"")) | J9: =IF(AND($C9="Objetivo",J$5>=$F9,J$5<=$F9+$G9-1),2,IF(AND($C9="Marco",J$5>=$F9,J$5<=$F9+$G9-1),1,"")) | K9: =IF(AND($C9="Objetivo",K$5>=$F9,K$5<=$F9+$G9-1),2,IF(AND($C9="Marco",K$5>=$F9,K$5<=$F9+$G9-1),1,"")) | L9: =IF(AND($C9="Objetivo",L$5>=$F9,L$5<=$F9+$G9-1),2,IF(AND($C9="Marco",L$5>=$F9,L$5<=$F9+$G9-1),1,"")) | M9: =IF(AND($C9="Objetivo",M$5>=$F9,M$5<=$F9+$G9-1),2,IF(AND($C9="Marco",M$5>=$F9,M$5<=$F9+$G9-1),1,"")) | N9: =IF(AND($C9="Objetivo",N$5>=$F9,N$5<=$F9+$G9-1),2,IF(AND($C9="Marco",N$5>=$F9,N$5<=$F9+$G9-1),1,"")) | O9: =IF(AND($C9="Objetivo",O$5>=$F9,O$5<=$F9+$G9-1),2,IF(AND($C9="Marco",O$5>=$F9,O$5<=$F9+$G9-1),1,"")) | P9: =IF(AND($C9="Objetivo",P$5>=$F9,P$5<=$F9+$G9-1),2,IF(AND($C9="Marco",P$5>=$F9,P$5<=$F9+$G9-1),1,"")) | ... BL9: =IF(AND($C9="Objetivo",BL$5>=$F9,BL$5<=$F9+$G9-1),2,IF(AND($C9="Marco",BL$5>=$F9,BL$5<=$F9+$G9-1),1,""))
A10: Direcionar os integrantes a seus objetivos. | B10: Estruturar as ideias do projeto. | C10: Médio risco | D10: ='Dicionario EAP2'!G17 -> Todos os integrantes do grupo | E10: ='Dicionario EAP2'!T17 -> 1 | F10: ='Dicionario EAP2'!I17 -> 44425 | G10: 4 | I10: =IF(AND($C10="Objetivo",I$5>=$F10,I$5<=$F10+$G10-1),2,IF(AND($C10="Marco",I$5>=$F10,I$5<=$F10+$G10-1),1,"")) | J10: =IF(AND($C10="Objetivo",J$5>=$F10,J$5<=$F10+$G10-1),2,IF(AND($C10="Marco",J$5>=$F10,J$5<=$F10+$G10-1),1,"")) | K10: =IF(AND($C10="Objetivo",K$5>=$F10,K$5<=$F10+$G10-1),2,IF(AND($C10="Marco",K$5>=$F10,K$5<=$F10+$G10-1),1,"")) | L10: =IF(AND($C10="Objetivo",L$5>=$F10,L$5<=$F10+$G10-1),2,IF(AND($C10="Marco",L$5>=$F10,L$5<=$F10+$G10-1),1,"")) | M10: =IF(AND($C10="Objetivo",M$5>=$F10,M$5<=$F10+$G10-1),2,IF(AND($C10="Marco",M$5>=$F10,M$5<=$F10+$G10-1),1,"")) | N10: =IF(AND($C10="Objetivo",N$5>=$F10,N$5<=$F10+$G10-1),2,IF(AND($C10="Marco",N$5>=$F10,N$5<=$F10+$G10-1),1,"")) | O10: =IF(AND($C10="Objetivo",O$5>=$F10,O$5<=$F10+$G10-1),2,IF(AND($C10="Marco",O$5>=$F10,O$5<=$F10+$G10-1),1,"")) | P10: =IF(AND($C10="Objetivo",P$5>=$F10,P$5<=$F10+$G10-1),2,IF(AND($C10="Marco",P$5>=$F10,P$5<=$F10+$G10-1),1,"")) | ... BL10: =IF(AND($C10="Objetivo",BL$5>=$F10,BL$5<=$F10+$G10-1),2,IF(AND($C10="Marco",BL$5>=$F10,BL$5<=$F10+$G10-1),1,""))
A11: Facilitar o reconhecimento das limitações e acrecismos dos integrantes do Projeto. | B11: verificar as forças e fraquezas de todos os integrantes do grupo. | C11: Médio risco | D11: ='Dicionario EAP2'!G18 -> Todos os integrantes do grupo | E11: ='Dicionario EAP2'!T18 -> 1 | F11: ='Dicionario EAP2'!I18 -> 44421 | G11: 5
A12: Atribuição de reponsabilidades de integrantes expecificos em determinadas temas. | B12: Atribuir responsabilidades a todos os integrantes do grupo. | C12: Médio risco | D12: ='Dicionario EAP2'!G19 -> Todos os integrantes do grupo | E12: ='Dicionario EAP2'!T19 -> 1 | F12: ='Dicionario EAP2'!I19 -> 44427 | G12: 1
A13: Gerar um aprimoramento no que já foi feito. | B13: Revisar o trabalho | C13: Baixo risco | D13: ='Dicionario EAP2'!G20 -> Todos os integrantes do grupo | E13: ='Dicionario EAP2'!T20 -> 1 | F13: ='Dicionario EAP2'!I20 -> 44432 | G13: 2 | I13: =IF(AND($C13="Objetivo",I$5>=$F13,I$5<=$F13+$G13-1),2,IF(AND($C13="Marco",I$5>=$F13,I$5<=$F13+$G13-1),1,"")) | J13: =IF(AND($C13="Objetivo",J$5>=$F13,J$5<=$F13+$G13-1),2,IF(AND($C13="Marco",J$5>=$F13,J$5<=$F13+$G13-1),1,"")) | K13: =IF(AND($C13="Objetivo",K$5>=$F13,K$5<=$F13+$G13-1),2,IF(AND($C13="Marco",K$5>=$F13,K$5<=$F13+$G13-1),1,"")) | L13: =IF(AND($C13="Objetivo",L$5>=$F13,L$5<=$F13+$G13-1),2,IF(AND($C13="Marco",L$5>=$F13,L$5<=$F13+$G13-1),1,"")) | M13: =IF(AND($C13="Objetivo",M$5>=$F13,M$5<=$F13+$G13-1),2,IF(AND($C13="Marco",M$5>=$F13,M$5<=$F13+$G13-1),1,"")) | N13: =IF(AND($C13="Objetivo",N$5>=$F13,N$5<=$F13+$G13-1),2,IF(AND($C13="Marco",N$5>=$F13,N$5<=$F13+$G13-1),1,"")) | O13: =IF(AND($C13="Objetivo",O$5>=$F13,O$5<=$F13+$G13-1),2,IF(AND($C13="Marco",O$5>=$F13,O$5<=$F13+$G13-1),1,"")) | P13: =IF(AND($C13="Objetivo",P$5>=$F13,P$5<=$F13+$G13-1),2,IF(AND($C13="Marco",P$5>=$F13,P$5<=$F13+$G13-1),1,"")) | ... BL13: =IF(AND($C13="Objetivo",BL$5>=$F13,BL$5<=$F13+$G13-1),2,IF(AND($C13="Marco",BL$5>=$F13,BL$5<=$F13+$G13-1),1,""))
A14: Cumprir com os criterios passados em sala de aula e do PMBOK. | B14: Validação | C14: Médio risco | D14: ='Dicionario EAP2'!G21 -> Todos os integrantes do grupo | E14: ='Dicionario EAP2'!T21 -> 1 | F14: ='Dicionario EAP2'!I21 -> 44434 | G14: 2 | I14: =IF(AND($C14="Objetivo",I$5>=$F14,I$5<=$F14+$G14-1),2,IF(AND($C14="Marco",I$5>=$F14,I$5<=$F14+$G14-1),1,"")) | J14: =IF(AND($C14="Objetivo",J$5>=$F14,J$5<=$F14+$G14-1),2,IF(AND($C14="Marco",J$5>=$F14,J$5<=$F14+$G14-1),1,"")) | K14: =IF(AND($C14="Objetivo",K$5>=$F14,K$5<=$F14+$G14-1),2,IF(AND($C14="Marco",K$5>=$F14,K$5<=$F14+$G14-1),1,"")) | L14: =IF(AND($C14="Objetivo",L$5>=$F14,L$5<=$F14+$G14-1),2,IF(AND($C14="Marco",L$5>=$F14,L$5<=$F14+$G14-1),1,"")) | M14: =IF(AND($C14="Objetivo",M$5>=$F14,M$5<=$F14+$G14-1),2,IF(AND($C14="Marco",M$5>=$F14,M$5<=$F14+$G14-1),1,"")) | N14: =IF(AND($C14="Objetivo",N$5>=$F14,N$5<=$F14+$G14-1),2,IF(AND($C14="Marco",N$5>=$F14,N$5<=$F14+$G14-1),1,"")) | O14: =IF(AND($C14="Objetivo",O$5>=$F14,O$5<=$F14+$G14-1),2,IF(AND($C14="Marco",O$5>=$F14,O$5<=$F14+$G14-1),1,"")) | P14: =IF(AND($C14="Objetivo",P$5>=$F14,P$5<=$F14+$G14-1),2,IF(AND($C14="Marco",P$5>=$F14,P$5<=$F14+$G14-1),1,"")) | ... BL14: =IF(AND($C14="Objetivo",BL$5>=$F14,BL$5<=$F14+$G14-1),2,IF(AND($C14="Marco",BL$5>=$F14,BL$5<=$F14+$G14-1),1,""))
A15: Definir e separar as principais renponsabilidades em etapas. | B15: Definir como e quando serão realizadas as atividas e etapas do projeto. | C15: Baixo risco | D15: ='Dicionario EAP2'!G22 -> Todos os integrantes do grupo | E15: ='Dicionario EAP2'!T22 -> 1 | F15: ='Dicionario EAP2'!I22 -> 44432 | G15: 11 | I15: =IF(AND($C15="Objetivo",I$5>=$F15,I$5<=$F15+$G15-1),2,IF(AND($C15="Marco",I$5>=$F15,I$5<=$F15+$G15-1),1,"")) | J15: =IF(AND($C15="Objetivo",J$5>=$F15,J$5<=$F15+$G15-1),2,IF(AND($C15="Marco",J$5>=$F15,J$5<=$F15+$G15-1),1,"")) | K15: =IF(AND($C15="Objetivo",K$5>=$F15,K$5<=$F15+$G15-1),2,IF(AND($C15="Marco",K$5>=$F15,K$5<=$F15+$G15-1),1,"")) | L15: =IF(AND($C15="Objetivo",L$5>=$F15,L$5<=$F15+$G15-1),2,IF(AND($C15="Marco",L$5>=$F15,L$5<=$F15+$G15-1),1,"")) | M15: =IF(AND($C15="Objetivo",M$5>=$F15,M$5<=$F15+$G15-1),2,IF(AND($C15="Marco",M$5>=$F15,M$5<=$F15+$G15-1),1,"")) | N15: =IF(AND($C15="Objetivo",N$5>=$F15,N$5<=$F15+$G15-1),2,IF(AND($C15="Marco",N$5>=$F15,N$5<=$F15+$G15-1),1,"")) | O15: =IF(AND($C15="Objetivo",O$5>=$F15,O$5<=$F15+$G15-1),2,IF(AND($C15="Marco",O$5>=$F15,O$5<=$F15+$G15-1),1,"")) | P15: =IF(AND($C15="Objetivo",P$5>=$F15,P$5<=$F15+$G15-1),2,IF(AND($C15="Marco",P$5>=$F15,P$5<=$F15+$G15-1),1,"")) | ... BL15: =IF(AND($C15="Objetivo",BL$5>=$F15,BL$5<=$F15+$G15-1),2,IF(AND($C15="Marco",BL$5>=$F15,BL$5<=$F15+$G15-1),1,""))
A16: Desmembrar as etapas em tarefas. | B16: Definir como e quando serão realizadas as atividas e etapas do projeto. | C16: Baixo risco | D16: ='Dicionario EAP2'!G23 -> Todos os integrantes do grupo | E16: ='Dicionario EAP2'!T23 -> 1 | F16: ='Dicionario EAP2'!I23 -> 44432 | G16: 13
A17: Direcionar de maneira mais profundada a todos os processos do projeto. | B17: Descrever as tarefas a serem executadas pelos integrantes baseado na análise SWOT e RACI | C17: Baixo risco | D17: ='Dicionario EAP2'!G24 -> Todos os integrantes do grupo | E17: ='Dicionario EAP2'!T24 -> 1 | F17: ='Dicionario EAP2'!I24 -> 44434 | G17: 9
A18: Gerar um aprimoramento naquilo que já foi executado. | B18: Revisar o que se foi feito. | C18: Baixo risco | D18: ='Dicionario EAP2'!G25 -> Todos os integrantes do grupo | E18: ='Dicionario EAP2'!T25 -> 1 | F18: ='Dicionario EAP2'!I25 -> 44439 | G18: 11
A19: Cumprir com os criterios passados em sala de aula e do PMBOK. | B19: validar o trabalho que foi feito nessa etapa | C19: Alto risco | D19: ='Dicionario EAP2'!G26 -> Todos os integrantes do grupo | E19: ='Dicionario EAP2'!T26 -> 1 | F19: ='Dicionario EAP2'!I26 -> 44439 | G19: 12
